Workbook

Sheet README
A1: STPI calculations — Stewart-Sinclair et al., Estuarine, Coastal and Shelf Science
A3: This workbook calculates the Standard Tidal Position Index (STPI) for coastal wetland habitat boundaries across 47 New Zealand estuaries, combining tidal datum data with habitat elevation boundaries derived from ordinal/binomial regression.
A6: Sheet | B6: Contents
A7: tidal_datum_summary | B7: Estuary-specific HAT/LAT tidal datums from the TELEMAC-2D model (mean, min, max, node count). Source: 04_tidal_datum_summary.R.
A8: habitat_boundaries_raw | B8: Raw habitat elevation transition boundaries (m, referenced to NZVD2016) from weighted ordinal/binomial logistic regression, before conversion to STPI. Source: 03_ordinal_regression_boundaries.R.
A9: STPI_by_estuary | B9: STPI value for every habitat boundary in every estuary (Table 1 and Table 2 in the manuscript, combined). Includes live formulas so the calculation is auditable.
A10: national_summary_Table3 | B10: National median and IQR STPI values by habitat boundary, split by mangrove presence/absence (matches manuscript Table 3). Computed with live formulas referencing STPI_by_estuary.
A11: Table_S3_estuary_detail | B11: Absolute elevation (m) of tidal datum limits and habitat boundaries for each estuary (matches Supplementary Table S3).
A12: excluded_estuaries | B12: The three estuaries excluded from the final 47-estuary dataset, and why (see manuscript Methods > Study areas).
A14: STPI formula
A15: STPI = (En - MTL) / (HAT - MTL), where MTL is approximated as mean sea level (0 m on NZVD2016). Seagrass lower boundary is fixed at LAT and saltmarsh upper boundary is fixed at HAT in every estuary (these are imposed analytical limits, not regression-estimated transitions — see response to Reviewer 1, Comment 7). The seagrass-mangrove, mangrove-saltmarsh, and seagrass-saltmarsh (no-mangrove estuaries) boundaries are genuine regression-estimated transitions.
A17: Data provenance
A18: Full processing pipeline (DEM clipping, pixel sampling, regression, tidal summary) is archived at: [REPOSITORY URL / ZENODO DOI — add once created]. National 1 m DEM: LINZ New Zealand LiDAR 1m DEM (CC BY 4.0). Habitat polygons: Bulmer et al. (2024).

Sheet tidal_datum_summary
A1: Estuary | B1: LAT mean (m) | C1: LAT min (m) | D1: LAT max (m) | E1: HAT mean (m) | F1: HAT min (m) | G1: HAT max (m) | H1: MHWS10 mean (m) | I1: MHWS10 min (m) | J1: MHWS10 max (m) | K1: N nodes
A2: Akaroa Harbour | B2: -1.3333342 | C2: -1.3503501 | D2: -1.3091244 | E2: 1.3111372 | F2: 1.2894166 | G2: 1.3256921 | H2: 1.0592411 | I2: 1.0403944 | J2: 1.0713576 | K2: 2253
A3: Aotea Harbour System (AHS) | B3: -1.4473899 | C3: -1.8454642 | D3: -1.4070296 | E3: 1.5976072 | F3: 1.5296899 | G3: 1.884075 | H3: 1.3444484 | I3: 1.2939656 | J3: 1.5172747 | K3: 1453
A4: Avon-Heathcote River | B4: -0.17687696 | C4: -0.38317791 | D4: 0.29969209 | E4: 0.79979877 | F4: 0.71042419 | G4: 0.97349697 | H4: 0.72508874 | I4: 0.64289278 | J4: 0.85721075 | K4: 284
A5: Bluff Harbour | B5: -1.4752554 | C5: -1.7243534 | D5: 0.58792144 | E5: 1.4378684 | F5: 0.6012758 | G5: 1.5464206 | H5: 1.1799153 | I5: 0.59854853 | J5: 1.2561492 | K5: 219
A6: Coromandel Harbour | B6: -1.7082504 | C6: -1.7262148 | D6: -1.6766491 | E6: 1.7736673 | F6: 1.7178755 | G6: 1.7968222 | H6: 1.4578162 | I6: 1.4112972 | J6: 1.4788903 | K6: 1805
A7: Croisilles Harbour | B7: -2.1375541 | C7: -4.1215415 | D7: -0.71045542 | E7: 2.1638781 | F7: -4.1215281 | G7: 2.1811206 | H7: 1.7094054 | I7: -4.1215305 | J7: 1.7240467 | K7: 2579
A8: Firth of Thames | B8: -1.8784443 | C8: -1.9701641 | D8: -1.722735 | E8: 1.9660992 | F8: 1.8039867 | G8: 2.046742 | H8: 1.6243706 | I8: 1.4850028 | J8: 1.6947111 | K8: 9283
A9: Hokianga Harbour System | B9: -1.8429722 | C9: -1.9849243 | D9: -1.6248918 | E9: 1.8214825 | F9: 1.6667975 | G9: 1.9913875 | H9: 1.4848772 | I9: 1.3510305 | J9: 1.6218836 | K9: 3459
A10: Houhora Harbour | B10: -1.3250766 | C10: -1.3401797 | D10: -1.3053018 | E10: 1.2987936 | F10: 1.2844136 | G10: 1.3108889 | H10: 1.0648846 | I10: 1.039566 | J10: 1.0788319 | K10: 1334
A11: Kaipara Harbour System | B11: -1.8237948 | C11: -2.1547139 | D11: 0.31243944 | E11: 1.8183519 | F11: 1.4014935 | G11: 2.0841596 | H11: 1.5148786 | I11: 1.2674512 | J11: 1.7223146 | K11: 16722
A12: Kawhia Harbour System (KHS) | B12: -1.9205379 | C12: -1.9955428 | D12: -1.7252884 | E12: 1.9104036 | F12: 1.8230619 | G12: 1.949648 | H12: 1.5486663 | I12: 1.4932507 | J12: 1.5764441 | K12: 3048
A13: Lyttelton Harbour | B13: -1.3539847 | C13: -1.3805991 | D13: -1.0889173 | E13: 1.3787413 | F13: 1.257262 | G13: 1.401978 | H13: 1.1121398 | I13: 1.0538136 | J13: 1.1330237 | K13: 1211
... A48: Whitianga Harbour (MBS) | B48: -1.1071209 | C48: -1.1863979 | D48: -0.45966577 | E48: 1.1366477 | F48: 0.93573004 | G48: 1.16566 | H48: 0.93192037 | I48: 0.81358719 | J48: 0.94838083 | K48: 3123

Sheet habitat_boundaries_raw
A1: Estuary | B1: Estuary type | C1: Mangroves present? | D1: Seagrass|Mangroves boundary (m) | E1: Mangroves|Saltmarsh boundary (m) | F1: Seagrass|Saltmarsh boundary (m)
A2: Akaroa Harbour | B2: Deep drowned valley | C2: No | F2: -0.12403639
A3: Aotea Harbour System (AHS) | B3: Shallow drowned valley | C3: Yes | D3: 0.3445554 | E3: 0.81714751
A4: Avon-Heathcote River | B4: Tidal lagoon | C4: No | F4: 0.026919678
A5: Bluff Harbour | B5: Shallow drowned valley | C5: No | F5: 0.047711166
A6: Coromandel Harbour | B6: Shallow drowned valley | C6: Yes | D6: -0.46560647 | E6: 0.038463486
A7: Croisilles Harbour | B7: Deep drowned valley | C7: No | F7: -0.17431423
A8: Firth of Thames | B8: Coastal Embayment | C8: Yes | D8: -0.089262615 | E8: 0.83067443
A9: Hokianga Harbour System | B9: Shallow drowned valley | C9: Yes | D9: 0.34664651 | E9: 0.94411653
A10: Houhora Harbour | B10: Shallow drowned valley | C10: Yes | D10: 0.51913775 | E10: 0.66739118
A11: Kaipara Harbour System | B11: Shallow drowned valley | C11: Yes | D11: 0.32612467 | E11: 1.2011336
A12: Kawhia Harbour System (KHS) | B12: Shallow drowned valley | C12: Yes | D12: 0.34877835 | E12: 0.72006152
A13: Lyttelton Harbour | B13: Deep drowned valley | C13: No | F13: 0.058653473
A14: Mahurangi Harbour System | B14: Shallow drowned valley | C14: Yes | D14: 0.10639267 | E14: 0.50491698
A15: Manaia Harbour | B15: Shallow drowned valley | C15: Yes | D15: -0.41378805 | E15: 0.12589168
A16: Mangonui Harbour | B16: Shallow drowned valley | C16: Yes | D16: 0.122286 | E16: 0.59061353
A17: Manukau Harbour System (MHS) | B17: Shallow drowned valley | C17: Yes | D17: 0.1209267 | E17: 0.8255092
A18: Moutere Inlet | B18: Shallow drowned valley | C18: No | F18: 0.74974198
A19: Nelson Haven | B19: Tidal lagoon | C19: No | F19: 0.60023546
A20: New River (Oreti) Estuary | B20: Shallow drowned valley | C20: No | F20: -0.28180925
A21: Ohiwa Harbour | B21: Deep drowned valley | C21: Yes | D21: -0.046357681 | E21: 0.36246349
A22: Opua Inlet System | B22: Deep drowned valley | C22: Yes | D22: 0.12751305 | E22: 0.51064781
A23: Otago Harbour | B23: Deep drowned valley | C23: No | F23: -0.50971428
A24: Parengarenga Harbour System | B24: Shallow drowned valley | C24: Yes | D24: -0.13222716 | E24: 0.68677336
A25: Pelorous/Kenepuru Sound | B25: Deep drowned valley | C25: No | F25: -0.42303512
A26: Porirua Harbour | B26: Shallow drowned valley | C26: No | F26: -0.24607182
A27: Port Fitzroy/Port Albercrombie | B27: Deep drowned valley | C27: Yes | D27: -0.58908079 | E27: -0.40849157
A28: Port Underwood | B28: Deep drowned valley | C28: No | F28: -0.083254938
A29: Queen Charlotte Sound (Totaranui) | B29: Deep drowned valley | C29: No | F29: -0.14417708
A30: Raglan Harbour System (RHS) | B30: Shallow drowned valley | C30: Yes | D30: 0.27063823 | E30: 0.72980844
A31: Rangaunu Harbour | B31: Shallow drowned valley | C31: Yes | D31: 0.12779234 | E31: 0.79462769
A32: Ruataniwha Inlet | B32: Tidal lagoon | C32: No | F32: 0.44230742
A33: Tairua Harbour | B33: Tidal lagoon | C33: Yes | D33: -0.27144981 | E33: -0.026760072
A34: Tamaki River | B34: Shallow drowned valley | C34: Yes | D34: -0.036132994 | E34: 0.64976488
A35: Tauranga Harbour System | B35: Shallow drowned valley | C35: Yes | D35: -0.27977011 | E35: 0.25758945
A36: Te Puna /Kerikeri Inlet System | B36: Deep drowned valley | C36: Yes | D36: -0.21897735 | E36: 0.23297602
A37: Waihi Estuary | B37: Tidal lagoon | C37: Yes | D37: 0.1535732 | E37: 0.27571546
A38: Waikawa Harbour | B38: Tidal lagoon | C38: No | F38: -0.25165342
A39: Waimea Inlet | B39: Shallow drowned valley | C39: No | F39: 0.74402516
A40: Waitemata Harbour System | B40: Shallow drowned valley | C40: Yes | D40: 0.21445235 | E40: 0.68967283
...

Sheet STPI_by_estuary
A1: Estuary | B1: Mangroves present? | C1: LAT (m) | D1: HAT (m) | E1: Seagrass lower STPI (imposed = LAT/HAT) | F1: Seagrass|Mangrove STPI (estimated, mangrove estuaries only) | G1: Mangrove|Saltmarsh STPI (estimated, mangrove estuaries only) | H1: Seagrass|Saltmarsh STPI (estimated, no-mangrove estuaries only) | I1: Saltmarsh upper STPI (imposed = HAT/HAT = 1) | J1: Seagrass lower STPI (mangrove estuaries only) | K1: Seagrass lower STPI (no-mangrove estuaries only) | L1: Saltmarsh upper STPI (mangrove estuaries only) | M1: Saltmarsh upper STPI (no-mangrove estuaries only)
A2: Akaroa Harbour | B2: No | C2: -1.3333342 | D2: 1.3111372 | E2: =(C2-0)/(D2-0) | H2: =(-0.12403639-0)/(D2-0) | I2: =(D2-0)/(D2-0) | J2: =IF(B2="Yes",E2,"") | K2: =IF(B2="No",E2,"") | L2: =IF(B2="Yes",I2,"") | M2: =IF(B2="No",I2,"")
A3: Aotea Harbour System (AHS) | B3: Yes | C3: -1.4473899 | D3: 1.5976072 | E3: =(C3-0)/(D3-0) | F3: =(0.344555398-0)/(D3-0) | G3: =(0.817147506-0)/(D3-0) | I3: =(D3-0)/(D3-0) | J3: =IF(B3="Yes",E3,"") | K3: =IF(B3="No",E3,"") | L3: =IF(B3="Yes",I3,"") | M3: =IF(B3="No",I3,"")
A4: Avon-Heathcote River | B4: No | C4: -0.17687696 | D4: 0.79979877 | E4: =(C4-0)/(D4-0) | H4: =(0.026919678-0)/(D4-0) | I4: =(D4-0)/(D4-0) | J4: =IF(B4="Yes",E4,"") | K4: =IF(B4="No",E4,"") | L4: =IF(B4="Yes",I4,"") | M4: =IF(B4="No",I4,"")
A5: Bluff Harbour | B5: No | C5: -1.4752554 | D5: 1.4378684 | E5: =(C5-0)/(D5-0) | H5: =(0.047711166-0)/(D5-0) | I5: =(D5-0)/(D5-0) | J5: =IF(B5="Yes",E5,"") | K5: =IF(B5="No",E5,"") | L5: =IF(B5="Yes",I5,"") | M5: =IF(B5="No",I5,"")
A6: Coromandel Harbour | B6: Yes | C6: -1.7082504 | D6: 1.7736673 | E6: =(C6-0)/(D6-0) | F6: =(-0.465606469-0)/(D6-0) | G6: =(0.038463486-0)/(D6-0) | I6: =(D6-0)/(D6-0) | J6: =IF(B6="Yes",E6,"") | K6: =IF(B6="No",E6,"") | L6: =IF(B6="Yes",I6,"") | M6: =IF(B6="No",I6,"")
A7: Croisilles Harbour | B7: No | C7: -2.1375541 | D7: 2.1638781 | E7: =(C7-0)/(D7-0) | H7: =(-0.174314232-0)/(D7-0) | I7: =(D7-0)/(D7-0) | J7: =IF(B7="Yes",E7,"") | K7: =IF(B7="No",E7,"") | L7: =IF(B7="Yes",I7,"") | M7: =IF(B7="No",I7,"")
A8: Firth of Thames | B8: Yes | C8: -1.8784443 | D8: 1.9660992 | E8: =(C8-0)/(D8-0) | F8: =(-0.089262615-0)/(D8-0) | G8: =(0.830674427-0)/(D8-0) | I8: =(D8-0)/(D8-0) | J8: =IF(B8="Yes",E8,"") | K8: =IF(B8="No",E8,"") | L8: =IF(B8="Yes",I8,"") | M8: =IF(B8="No",I8,"")
A9: Hokianga Harbour System | B9: Yes | C9: -1.8429722 | D9: 1.8214825 | E9: =(C9-0)/(D9-0) | F9: =(0.346646507-0)/(D9-0) | G9: =(0.944116533-0)/(D9-0) | I9: =(D9-0)/(D9-0) | J9: =IF(B9="Yes",E9,"") | K9: =IF(B9="No",E9,"") | L9: =IF(B9="Yes",I9,"") | M9: =IF(B9="No",I9,"")
A10: Houhora Harbour | B10: Yes | C10: -1.3250766 | D10: 1.2987936 | E10: =(C10-0)/(D10-0) | F10: =(0.519137749-0)/(D10-0) | G10: =(0.667391178-0)/(D10-0) | I10: =(D10-0)/(D10-0) | J10: =IF(B10="Yes",E10,"") | K10: =IF(B10="No",E10,"") | L10: =IF(B10="Yes",I10,"") | M10: =IF(B10="No",I10,"")
A11: Kaipara Harbour System | B11: Yes | C11: -1.8237948 | D11: 1.8183519 | E11: =(C11-0)/(D11-0) | F11: =(0.326124675-0)/(D11-0) | G11: =(1.201133625-0)/(D11-0) | I11: =(D11-0)/(D11-0) | J11: =IF(B11="Yes",E11,"") | K11: =IF(B11="No",E11,"") | L11: =IF(B11="Yes",I11,"") | M11: =IF(B11="No",I11,"")
A12: Kawhia Harbour System (KHS) | B12: Yes | C12: -1.9205379 | D12: 1.9104036 | E12: =(C12-0)/(D12-0) | F12: =(0.348778349-0)/(D12-0) | G12: =(0.720061522-0)/(D12-0) | I12: =(D12-0)/(D12-0) | J12: =IF(B12="Yes",E12,"") | K12: =IF(B12="No",E12,"") | L12: =IF(B12="Yes",I12,"") | M12: =IF(B12="No",I12,"")
A13: Lyttelton Harbour | B13: No | C13: -1.3539847 | D13: 1.3787413 | E13: =(C13-0)/(D13-0) | H13: =(0.058653473-0)/(D13-0) | I13: =(D13-0)/(D13-0) | J13: =IF(B13="Yes",E13,"") | K13: =IF(B13="No",E13,"") | L13: =IF(B13="Yes",I13,"") | M13: =IF(B13="No",I13,"")
A14: Mahurangi Harbour System | B14: Yes | C14: -1.5884287 | D14: 1.6332253 | E14: =(C14-0)/(D14-0) | F14: =(0.106392669-0)/(D14-0) | G14: =(0.504916981-0)/(D14-0) | I14: =(D14-0)/(D14-0) | J14: =IF(B14="Yes",E14,"") | K14: =IF(B14="No",E14,"") | L14: =IF(B14="Yes",I14,"") | M14: =IF(B14="No",I14,"")
A15: Manaia Harbour | B15: Yes | C15: -1.7220391 | D15: 1.7941374 | E15: =(C15-0)/(D15-0) | F15: =(-0.41378805-0)/(D15-0) | G15: =(0.125891681-0)/(D15-0) | I15: =(D15-0)/(D15-0) | J15: =IF(B15="Yes",E15,"") | K15: =IF(B15="No",E15,"") | L15: =IF(B15="Yes",I15,"") | M15: =IF(B15="No",I15,"")
A16: Mangonui Harbour | B16: Yes | C16: -1.3150442 | D16: 1.3010899 | E16: =(C16-0)/(D16-0) | F16: =(0.122286004-0)/(D16-0) | G16: =(0.590613533-0)/(D16-0) | I16: =(D16-0)/(D16-0) | J16: =IF(B16="Yes",E16,"") | K16: =IF(B16="No",E16,"") | L16: =IF(B16="Yes",I16,"") | M16: =IF(B16="No",I16,"")
A17: Manukau Harbour System (MHS) | B17: Yes | C17: -2.1423352 | D17: 2.1010926 | E17: =(C17-0)/(D17-0) | F17: =(0.1209267-0)/(D17-0) | G17: =(0.825509198-0)/(D17-0) | I17: =(D17-0)/(D17-0) | J17: =IF(B17="Yes",E17,"") | K17: =IF(B17="No",E17,"") | L17: =IF(B17="Yes",I17,"") | M17: =IF(B17="No",I17,"")
A18: Moutere Inlet | B18: No | C18: -2.1790654 | D18: 2.2513082 | E18: =(C18-0)/(D18-0) | H18: =(0.749741982-0)/(D18-0) | I18: =(D18-0)/(D18-0) | J18: =IF(B18="Yes",E18,"") | K18: =IF(B18="No",E18,"") | L18: =IF(B18="Yes",I18,"") | M18: =IF(B18="No",I18,"")
A19: Nelson Haven | B19: No | C19: -2.1571807 | D19: 2.204831 | E19: =(C19-0)/(D19-0) | H19: =(0.60023546-0)/(D19-0) | I19: =(D19-0)/(D19-0) | J19: =IF(B19="Yes",E19,"") | K19: =IF(B19="No",E19,"") | L19: =IF(B19="Yes",I19,"") | M19: =IF(B19="No",I19,"")
A20: New River (Oreti) Estuary | B20: No | C20: -1.0602567 | D20: 1.2518125 | E20: =(C20-0)/(D20-0) | H20: =(-0.281809247-0)/(D20-0) | I20: =(D20-0)/(D20-0) | J20: =IF(B20="Yes",E20,"") | K20: =IF(B20="No",E20,"") | L20: =IF(B20="Yes",I20,"") | M20: =IF(B20="No",I20,"")
A21: Ohiwa Harbour | B21: Yes | C21: -0.99043253 | D21: 1.0519274 | E21: =(C21-0)/(D21-0) | F21: =(-0.046357681-0)/(D21-0) | G21: =(0.36246349-0)/(D21-0) | I21: =(D21-0)/(D21-0) | J21: =IF(B21="Yes",E21,"") | K21: =IF(B21="No",E21,"") | L21: =IF(B21="Yes",I21,"") | M21: =IF(B21="No",I21,"")
A22: Opua Inlet System | B22: Yes | C22: -1.3216886 | D22: 1.327243 | E22: =(C22-0)/(D22-0) | F22: =(0.127513055-0)/(D22-0) | G22: =(0.510647812-0)/(D22-0) | I22: =(D22-0)/(D22-0) | J22: =IF(B22="Yes",E22,"") | K22: =IF(B22="No",E22,"") | L22: =IF(B22="Yes",I22,"") | M22: =IF(B22="No",I22,"")
A23: Otago Harbour | B23: No | C23: -1.2821469 | D23: 1.2315152 | E23: =(C23-0)/(D23-0) | H23: =(-0.509714282-0)/(D23-0) | I23: =(D23-0)/(D23-0) | J23: =IF(B23="Yes",E23,"") | K23: =IF(B23="No",E23,"") | L23: =IF(B23="Yes",I23,"") | M23: =IF(B23="No",I23,"")
A24: Parengarenga Harbour System | B24: Yes | C24: -1.1827891 | D24: 1.240361 | E24: =(C24-0)/(D24-0) | F24: =(-0.132227155-0)/(D24-0) | G24: =(0.686773359-0)/(D24-0) | I24: =(D24-0)/(D24-0) | J24: =IF(B24="Yes",E24,"") | K24: =IF(B24="No",E24,"") | L24: =IF(B24="Yes",I24,"") | M24: =IF(B24="No",I24,"")
A25: Pelorous/Kenepuru Sound | B25: No | C25: -1.4632691 | D25: 1.5104552 | E25: =(C25-0)/(D25-0) | H25: =(-0.423035119-0)/(D25-0) | I25: =(D25-0)/(D25-0) | J25: =IF(B25="Yes",E25,"") | K25: =IF(B25="No",E25,"") | L25: =IF(B25="Yes",I25,"") | M25: =IF(B25="No",I25,"")
A26: Porirua Harbour | B26: No | C26: -0.73674047 | D26: 0.79634164 | E26: =(C26-0)/(D26-0) | H26: =(-0.246071821-0)/(D26-0) | I26: =(D26-0)/(D26-0) | J26: =IF(B26="Yes",E26,"") | K26: =IF(B26="No",E26,"") | L26: =IF(B26="Yes",I26,"") | M26: =IF(B26="No",I26,"")
A27: Port Fitzroy/Port Albercrombie | B27: Yes | C27: -1.3646339 | D27: 1.3546574 | E27: =(C27-0)/(D27-0) | F27: =(-0.589080792-0)/(D27-0) | G27: =(-0.408491568-0)/(D27-0) | I27: =(D27-0)/(D27-0) | J27: =IF(B27="Yes",E27,"") | K27: =IF(B27="No",E27,"") | L27: =IF(B27="Yes",I27,"") | M27: =IF(B27="No",I27,"")
A28: Port Underwood | B28: No | C28: -0.84981074 | D28: 0.83854983 | E28: =(C28-0)/(D28-0) | H28: =(-0.083254938-0)/(D28-0) | I28: =(D28-0)/(D28-0) | J28: =IF(B28="Yes",E28,"") | K28: =IF(B28="No",E28,"") | L28: =IF(B28="Yes",I28,"") | M28: =IF(B28="No",I28,"")
A29: Queen Charlotte Sound (Totaranui) | B29: No | C29: -0.9282985 | D29: 0.88406131 | E29: =(C29-0)/(D29-0) | H29: =(-0.144177079-0)/(D29-0) | I29: =(D29-0)/(D29-0) | J29: =IF(B29="Yes",E29,"") | K29: =IF(B29="No",E29,"") | L29: =IF(B29="Yes",I29,"") | M29: =IF(B29="No",I29,"")
A30: Raglan Harbour System (RHS) | B30: Yes | C30: -1.9103609 | D30: 1.9236261 | E30: =(C30-0)/(D30-0) | F30: =(0.270638229-0)/(D30-0) | G30: =(0.72980844-0)/(D30-0) | I30: =(D30-0)/(D30-0) | J30: =IF(B30="Yes",E30,"") | K30: =IF(B30="No",E30,"") | L30: =IF(B30="Yes",I30,"") | M30: =IF(B30="No",I30,"")
A31: Rangaunu Harbour | B31: Yes | C31: -1.359596 | D31: 1.3687909 | E31: =(C31-0)/(D31-0) | F31: =(0.127792338-0)/(D31-0) | G31: =(0.794627689-0)/(D31-0) | I31: =(D31-0)/(D31-0) | J31: =IF(B31="Yes",E31,"") | K31: =IF(B31="No",E31,"") | L31: =IF(B31="Yes",I31,"") | M31: =IF(B31="No",I31,"")
A32: Ruataniwha Inlet | B32: No | C32: -2.2857021 | D32: 2.3186724 | E32: =(C32-0)/(D32-0) | H32: =(0.442307422-0)/(D32-0) | I32: =(D32-0)/(D32-0) | J32: =IF(B32="Yes",E32,"") | K32: =IF(B32="No",E32,"") | L32: =IF(B32="Yes",I32,"") | M32: =IF(B32="No",I32,"")
A33: Tairua Harbour | B33: Yes | C33: -0.60917025 | D33: 0.9230107 | E33: =(C33-0)/(D33-0) | F33: =(-0.271449809-0)/(D33-0) | G33: =(-0.026760072-0)/(D33-0) | I33: =(D33-0)/(D33-0) | J33: =IF(B33="Yes",E33,"") | K33: =IF(B33="No",E33,"") | L33: =IF(B33="Yes",I33,"") | M33: =IF(B33="No",I33,"")
A34: Tamaki River | B34: Yes | C34: -1.7465622 | D34: 1.7943851 | E34: =(C34-0)/(D34-0) | F34: =(-0.036132994-0)/(D34-0) | G34: =(0.649764875-0)/(D34-0) | I34: =(D34-0)/(D34-0) | J34: =IF(B34="Yes",E34,"") | K34: =IF(B34="No",E34,"") | L34: =IF(B34="Yes",I34,"") | M34: =IF(B34="No",I34,"")
A35: Tauranga Harbour System | B35: Yes | C35: -1.1146644 | D35: 1.1175141 | E35: =(C35-0)/(D35-0) | F35: =(-0.279770114-0)/(D35-0) | G35: =(0.25758945-0)/(D35-0) | I35: =(D35-0)/(D35-0) | J35: =IF(B35="Yes",E35,"") | K35: =IF(B35="No",E35,"") | L35: =IF(B35="Yes",I35,"") | M35: =IF(B35="No",I35,"")
A36: Te Puna /Kerikeri Inlet System | B36: Yes | C36: -1.309226 | D36: 1.3020098 | E36: =(C36-0)/(D36-0) | F36: =(-0.218977349-0)/(D36-0) | G36: =(0.232976024-0)/(D36-0) | I36: =(D36-0)/(D36-0) | J36: =IF(B36="Yes",E36,"") | K36: =IF(B36="No",E36,"") | L36: =IF(B36="Yes",I36,"") | M36: =IF(B36="No",I36,"")
A37: Waihi Estuary | B37: Yes | C37: -0.57145173 | D37: 0.81491686 | E37: =(C37-0)/(D37-0) | F37: =(0.153573205-0)/(D37-0) | G37: =(0.275715458-0)/(D37-0) | I37: =(D37-0)/(D37-0) | J37: =IF(B37="Yes",E37,"") | K37: =IF(B37="No",E37,"") | L37: =IF(B37="Yes",I37,"") | M37: =IF(B37="No",I37,"")
A38: Waikawa Harbour | B38: No | C38: -1.2722603 | D38: 1.3246956 | E38: =(C38-0)/(D38-0) | H38: =(-0.251653419-0)/(D38-0) | I38: =(D38-0)/(D38-0) | J38: =IF(B38="Yes",E38,"") | K38: =IF(B38="No",E38,"") | L38: =IF(B38="Yes",I38,"") | M38: =IF(B38="No",I38,"")
A39: Waimea Inlet | B39: No | C39: -2.0672088 | D39: 2.1645137 | E39: =(C39-0)/(D39-0) | H39: =(0.744025164-0)/(D39-0) | I39: =(D39-0)/(D39-0) | J39: =IF(B39="Yes",E39,"") | K39: =IF(B39="No",E39,"") | L39: =IF(B39="Yes",I39,"") | M39: =IF(B39="No",I39,"")
A40: Waitemata Harbour System | B40: Yes | C40: -1.7709589 | D40: 1.86066 | E40: =(C40-0)/(D40-0) | F40: =(0.214452349-0)/(D40-0) | G40: =(0.689672833-0)/(D40-0) | I40: =(D40-0)/(D40-0) | J40: =IF(B40="Yes",E40,"") | K40: =IF(B40="No",E40,"") | L40: =IF(B40="Yes",I40,"") | M40: =IF(B40="No",I40,"")
...

Sheet national_summary_Table3
A1: National median and IQR STPI values by habitat boundary (matches manuscript Table 3)
A3: Habitat boundary | B3: Median STPI (with mangroves) | C3: IQR (with mangroves) | D3: Median STPI (without mangroves) | E3: IQR (without mangroves)
A4: Seagrass lower | B4: =MEDIAN(STPI_by_estuary!J2:J48) | C4: =QUARTILE(STPI_by_estuary!J2:J48,3)-QUARTILE(STPI_by_estuary!J2:J48,1) | D4: =MEDIAN(STPI_by_estuary!K2:K48) | E4: =QUARTILE(STPI_by_estuary!K2:K48,3)-QUARTILE(STPI_by_estuary!K2:K48,1)
A5: Seagrass upper / Mangrove lower | B5: =MEDIAN(STPI_by_estuary!F2:F48) | C5: =QUARTILE(STPI_by_estuary!F2:F48,3)-QUARTILE(STPI_by_estuary!F2:F48,1) | D5: n/a | E5: n/a
A6: Mangrove upper / Saltmarsh lower | B6: =MEDIAN(STPI_by_estuary!G2:G48) | C6: =QUARTILE(STPI_by_estuary!G2:G48,3)-QUARTILE(STPI_by_estuary!G2:G48,1) | D6: n/a | E6: n/a
A7: Seagrass-Saltmarsh boundary | B7: n/a | C7: n/a | D7: =MEDIAN(STPI_by_estuary!H2:H48) | E7: =QUARTILE(STPI_by_estuary!H2:H48,3)-QUARTILE(STPI_by_estuary!H2:H48,1)
A8: Saltmarsh upper | B8: =MEDIAN(STPI_by_estuary!L2:L48) | C8: =QUARTILE(STPI_by_estuary!L2:L48,3)-QUARTILE(STPI_by_estuary!L2:L48,1) | D8: =MEDIAN(STPI_by_estuary!M2:M48) | E8: =QUARTILE(STPI_by_estuary!M2:M48,3)-QUARTILE(STPI_by_estuary!M2:M48,1)
A10: Values in this table should match manuscript Table 3 exactly. All formulas reference STPI_by_estuary directly — no values are hard-coded here, so this recalculates automatically if any estuary's tidal datum or boundary elevation is corrected.

Sheet Table_S3_estuary_detail
A1: Estuary | B1: Estuary type | C1: Mangroves present? | D1: LAT (m) | E1: Seagrass|Mangrove boundary (m) | F1: Mangrove|Saltmarsh boundary (m) | G1: Seagrass|Saltmarsh boundary (m) | H1: HAT (m)
A2: Akaroa Harbour | B2: Deep drowned valley | C2: No | D2: -1.3333342 | G2: -0.12403639 | H2: 1.3111372
A3: Aotea Harbour System (AHS) | B3: Shallow drowned valley | C3: Yes | D3: -1.4473899 | E3: 0.3445554 | F3: 0.81714751 | H3: 1.5976072
A4: Avon-Heathcote River | B4: Tidal lagoon | C4: No | D4: -0.17687696 | G4: 0.026919678 | H4: 0.79979877
A5: Bluff Harbour | B5: Shallow drowned valley | C5: No | D5: -1.4752554 | G5: 0.047711166 | H5: 1.4378684
A6: Coromandel Harbour | B6: Shallow drowned valley | C6: Yes | D6: -1.7082504 | E6: -0.46560647 | F6: 0.038463486 | H6: 1.7736673
A7: Croisilles Harbour | B7: Deep drowned valley | C7: No | D7: -2.1375541 | G7: -0.17431423 | H7: 2.1638781
A8: Firth of Thames | B8: Coastal Embayment | C8: Yes | D8: -1.8784443 | E8: -0.089262615 | F8: 0.83067443 | H8: 1.9660992
A9: Hokianga Harbour System | B9: Shallow drowned valley | C9: Yes | D9: -1.8429722 | E9: 0.34664651 | F9: 0.94411653 | H9: 1.8214825
A10: Houhora Harbour | B10: Shallow drowned valley | C10: Yes | D10: -1.3250766 | E10: 0.51913775 | F10: 0.66739118 | H10: 1.2987936
A11: Kaipara Harbour System | B11: Shallow drowned valley | C11: Yes | D11: -1.8237948 | E11: 0.32612467 | F11: 1.2011336 | H11: 1.8183519
A12: Kawhia Harbour System (KHS) | B12: Shallow drowned valley | C12: Yes | D12: -1.9205379 | E12: 0.34877835 | F12: 0.72006152 | H12: 1.9104036
A13: Lyttelton Harbour | B13: Deep drowned valley | C13: No | D13: -1.3539847 | G13: 0.058653473 | H13: 1.3787413
A14: Mahurangi Harbour System | B14: Shallow drowned valley | C14: Yes | D14: -1.5884287 | E14: 0.10639267 | F14: 0.50491698 | H14: 1.6332253
A15: Manaia Harbour | B15: Shallow drowned valley | C15: Yes | D15: -1.7220391 | E15: -0.41378805 | F15: 0.12589168 | H15: 1.7941374
A16: Mangonui Harbour | B16: Shallow drowned valley | C16: Yes | D16: -1.3150442 | E16: 0.122286 | F16: 0.59061353 | H16: 1.3010899
A17: Manukau Harbour System (MHS) | B17: Shallow drowned valley | C17: Yes | D17: -2.1423352 | E17: 0.1209267 | F17: 0.8255092 | H17: 2.1010926
A18: Moutere Inlet | B18: Shallow drowned valley | C18: No | D18: -2.1790654 | G18: 0.74974198 | H18: 2.2513082
A19: Nelson Haven | B19: Tidal lagoon | C19: No | D19: -2.1571807 | G19: 0.60023546 | H19: 2.204831
A20: New River (Oreti) Estuary | B20: Shallow drowned valley | C20: No | D20: -1.0602567 | G20: -0.28180925 | H20: 1.2518125
A21: Ohiwa Harbour | B21: Deep drowned valley | C21: Yes | D21: -0.99043253 | E21: -0.046357681 | F21: 0.36246349 | H21: 1.0519274
A22: Opua Inlet System | B22: Deep drowned valley | C22: Yes | D22: -1.3216886 | E22: 0.12751305 | F22: 0.51064781 | H22: 1.327243
A23: Otago Harbour | B23: Deep drowned valley | C23: No | D23: -1.2821469 | G23: -0.50971428 | H23: 1.2315152
A24: Parengarenga Harbour System | B24: Shallow drowned valley | C24: Yes | D24: -1.1827891 | E24: -0.13222716 | F24: 0.68677336 | H24: 1.240361
A25: Pelorous/Kenepuru Sound | B25: Deep drowned valley | C25: No | D25: -1.4632691 | G25: -0.42303512 | H25: 1.5104552
A26: Porirua Harbour | B26: Shallow drowned valley | C26: No | D26: -0.73674047 | G26: -0.24607182 | H26: 0.79634164
A27: Port Fitzroy/Port Albercrombie | B27: Deep drowned valley | C27: Yes | D27: -1.3646339 | E27: -0.58908079 | F27: -0.40849157 | H27: 1.3546574
A28: Port Underwood | B28: Deep drowned valley | C28: No | D28: -0.84981074 | G28: -0.083254938 | H28: 0.83854983
A29: Queen Charlotte Sound (Totaranui) | B29: Deep drowned valley | C29: No | D29: -0.9282985 | G29: -0.14417708 | H29: 0.88406131
A30: Raglan Harbour System (RHS) | B30: Shallow drowned valley | C30: Yes | D30: -1.9103609 | E30: 0.27063823 | F30: 0.72980844 | H30: 1.9236261
A31: Rangaunu Harbour | B31: Shallow drowned valley | C31: Yes | D31: -1.359596 | E31: 0.12779234 | F31: 0.79462769 | H31: 1.3687909
A32: Ruataniwha Inlet | B32: Tidal lagoon | C32: No | D32: -2.2857021 | G32: 0.44230742 | H32: 2.3186724
A33: Tairua Harbour | B33: Tidal lagoon | C33: Yes | D33: -0.60917025 | E33: -0.27144981 | F33: -0.026760072 | H33: 0.9230107
A34: Tamaki River | B34: Shallow drowned valley | C34: Yes | D34: -1.7465622 | E34: -0.036132994 | F34: 0.64976488 | H34: 1.7943851
A35: Tauranga Harbour System | B35: Shallow drowned valley | C35: Yes | D35: -1.1146644 | E35: -0.27977011 | F35: 0.25758945 | H35: 1.1175141
A36: Te Puna /Kerikeri Inlet System | B36: Deep drowned valley | C36: Yes | D36: -1.309226 | E36: -0.21897735 | F36: 0.23297602 | H36: 1.3020098
A37: Waihi Estuary | B37: Tidal lagoon | C37: Yes | D37: -0.57145173 | E37: 0.1535732 | F37: 0.27571546 | H37: 0.81491686
A38: Waikawa Harbour | B38: Tidal lagoon | C38: No | D38: -1.2722603 | G38: -0.25165342 | H38: 1.3246956
A39: Waimea Inlet | B39: Shallow drowned valley | C39: No | D39: -2.0672088 | G39: 0.74402516 | H39: 2.1645137
A40: Waitemata Harbour System | B40: Shallow drowned valley | C40: Yes | D40: -1.7709589 | E40: 0.21445235 | F40: 0.68967283 | H40: 1.86066
...

Sheet excluded_estuaries
A1: Estuary | B1: Reason excluded | C1: Habitat boundary data available? | D1: Tidal datum data available?
A2: Patterson Inlet / Big Glory Bay | B2: Habitat elevation data were entirely invalid (-9999 fill value) — no usable elevation samples for any habitat. | C2: No | D2: Yes
A3: Blueskin Bay | B3: TELEMAC tidal statistics were anomalous and could not be interpreted with confidence. | C3: Yes (seagrass-saltmarsh boundary estimated) — not used, since tidal datums could not be trusted | D3: Present but not usable
A4: Jacobs River | B4: Only saltmarsh habitat was mapped at this site; no second habitat class was present, so no elevation transition boundary could be estimated. | C4: No (no transition to estimate) | D4: Yes
